Workbook

Sheet Worksheet
A1: ОАО "Аньковское"
A2: Отчет за потребленную электроэнергию и мощность, Январь 2020 г.
A3: Счетчик № | B3: 25506893
A4: Тр.тока (коэф) | B4: 120
B5: Число расчетного месяца | C5: Время суток
C6: 0.00-1.00 | D6: 1.00-2.00 | E6: 2.00-3.00 | F6: 3.00-4.00 | G6: 4.00-5.00 | H6: 5.00-6.00 | I6: 6.00-7.00 | J6: 7.00-8.00 | K6: 8.00-9.00 | L6: 9.00-10.00 | M6: 10.00-11.00 | N6: 11.00-12.00 | O6: 12.00-13.00 | P6: 13.00-14.00 | Q6: 14.00-15.00 | R6: 15.00-16.00 | S6: 16.00-17.00 | T6: 17.00-18.00 | U6: 18.00-19.00 | V6: 19.00-20.00 | W6: 20.00-21.00 | X6: 21.00-22.00 | Y6: 22.00-23.00 | Z6: 23.00-24.00
B7: 1 | C7: 0.303 | D7: 0.3335 | E7: 0.3515 | F7: 0.3675 | G7: 0.363 | H7: 0.354 | I7: 0.3615 | J7: 0.3535 | K7: 0.3365 | L7: 0.337 | M7: 0.3255 | N7: 0.3395 | O7: 0.321 | P7: 0.3175 | Q7: 0.3155 | R7: 0.3145 | S7: 0.314 | T7: 0.334 | U7: 0.3095 | V7: 0.31 | W7: 0.3135 | X7: 0.3745 | Y7: 0.306 | Z7: 0.3015
B8: 2 | C8: 0.306 | D8: 0.2935 | E8: 0.2875 | F8: 0.2975 | G8: 0.2915 | H8: 0.2945 | I8: 0.321 | J8: 0.2995 | K8: 0.2995 | L8: 0.3535 | M8: 0.3755 | N8: 0.4045 | O8: 0.331 | P8: 0.289 | Q8: 0.295 | R8: 0.363 | S8: 0.411 | T8: 0.382 | U8: 0.3235 | V8: 0.321 | W8: 0.2945 | X8: 0.2935 | Y8: 0.308 | Z8: 0.2915
B9: 3 | C9: 0.305 | D9: 0.2975 | E9: 0.29 | F9: 0.2915 | G9: 0.301 | H9: 0.307 | I9: 0.5875 | J9: 0.642 | K9: 0.6955 | L9: 0.8215 | M9: 0.96 | N9: 0.919 | O9: 0.703 | P9: 0.4585 | Q9: 0.4535 | R9: 0.4755 | S9: 0.478 | T9: 0.4595 | U9: 0.403 | V9: 0.297 | W9: 0.307 | X9: 0.2865 | Y9: 0.2815 | Z9: 0.2785
B10: 4 | C10: 0.2695 | D10: 0.28 | E10: 0.292 | F10: 0.268 | G10: 0.2665 | H10: 0.3185 | I10: 0.544 | J10: 0.5725 | K10: 0.701 | L10: 0.8305 | M10: 0.985 | N10: 0.9865 | O10: 0.805 | P10: 0.5485 | Q10: 0.4315 | R10: 0.443 | S10: 0.401 | T10: 0.403 | U10: 0.4085 | V10: 0.3915 | W10: 0.333 | X10: 0.3215 | Y10: 0.3335 | Z10: 0.3515
B11: 5 | C11: 0.3205 | D11: 0.3085 | E11: 0.3155 | F11: 0.3285 | G11: 0.307 | H11: 0.369 | I11: 0.476 | J11: 0.4475 | K11: 0.4805 | L11: 0.4565 | M11: 0.4405 | N11: 0.459 | O11: 0.447 | P11: 0.436 | Q11: 0.3805 | R11: 0.419 | S11: 0.378 | T11: 0.3525 | U11: 0.367 | V11: 0.345 | W11: 0.348 | X11: 0.347 | Y11: 0.325 | Z11: 0.3245
B12: 6 | C12: 0.321 | D12: 0.324 | E12: 0.335 | F12: 0.3355 | G12: 0.328 | H12: 0.3475 | I12: 0.6195 | J12: 0.6875 | K12: 0.747 | L12: 0.908 | M12: 1.036 | N12: 0.9725 | O12: 0.832 | P12: 0.625 | Q12: 0.5615 | R12: 0.5305 | S12: 0.4805 | T12: 0.4355 | U12: 0.443 | V12: 0.442 | W12: 0.4005 | X12: 0.36 | Y12: 0.357 | Z12: 0.3495
B13: 7 | C13: 0.3655 | D13: 0.348 | E13: 0.3435 | F13: 0.3705 | G13: 0.3685 | H13: 0.364 | I13: 0.373 | J13: 0.357 | K13: 0.374 | L13: 0.412 | M13: 0.3705 | N13: 0.355 | O13: 0.344 | P13: 0.3475 | Q13: 0.355 | R13: 0.4185 | S13: 0.3545 | T13: 0.3525 | U13: 0.3495 | V13: 0.3675 | W13: 0.35 | X13: 0.3555 | Y13: 0.3295 | Z13: 0.3415
B14: 8 | C14: 0.3425 | D14: 0.329 | E14: 0.3515 | F14: 0.3555 | G14: 0.358 | H14: 0.35 | I14: 0.347 | J14: 0.495 | K14: 0.7165 | L14: 0.8255 | M14: 0.829 | N14: 0.9875 | O14: 0.8105 | P14: 0.558 | Q14: 0.4905 | R14: 0.4965 | S14: 0.458 | T14: 0.4315 | U14: 0.445 | V14: 0.437 | W14: 0.4155 | X14: 0.4335 | Y14: 0.418 | Z14: 0.4035
B15: 9 | C15: 0.3325 | D15: 0.34 | E15: 0.34 | F15: 0.3455 | G15: 0.3305 | H15: 0.391 | I15: 0.5245 | J15: 0.585 | K15: 0.658 | L15: 0.886 | M15: 0.9685 | N15: 1.015 | O15: 0.9465 | P15: 0.798 | Q15: 0.8015 | R15: 0.8425 | S15: 0.855 | T15: 0.7375 | U15: 0.7565 | V15: 0.7345 | W15: 0.677 | X15: 0.4955 | Y15: 0.427 | Z15: 0.417
B16: 10 | C16: 0.406 | D16: 0.395 | E16: 0.3915 | F16: 0.4 | G16: 0.418 | H16: 0.453 | I16: 0.79 | J16: 1.0045 | K16: 1.2165 | L16: 1.3335 | M16: 1.4375 | N16: 1.4395 | O16: 1.342 | P16: 1.0075 | Q16: 1.0565 | R16: 1.0425 | S16: 0.9665 | T16: 0.9085 | U16: 0.8995 | V16: 0.8595 | W16: 0.8905 | X16: 0.8845 | Y16: 0.84 | Z16: 0.776
B17: 11 | C17: 0.724 | D17: 0.759 | E17: 0.7805 | F17: 0.738 | G17: 0.6275 | H17: 0.502 | I17: 0.659 | J17: 0.834 | K17: 0.8905 | L17: 0.858 | M17: 0.9475 | N17: 0.9565 | O17: 0.8995 | P17: 0.6125 | Q17: 0.7705 | R17: 0.871 | S17: 0.8615 | T17: 0.792 | U17: 0.7545 | V17: 0.7515 | W17: 0.677 | X17: 0.5225 | Y17: 0.478 | Z17: 0.4615
B18: 12 | C18: 0.4625 | D18: 0.481 | E18: 0.5025 | F18: 0.482 | G18: 0.4765 | H18: 0.493 | I18: 0.8815 | J18: 1.033 | K18: 1.0925 | L18: 1.2245 | M18: 1.2885 | N18: 1.4125 | O18: 1.2435 | P18: 0.7945 | Q18: 0.785 | R18: 0.8345 | S18: 0.8865 | T18: 0.809 | U18: 0.7065 | V18: 0.7295 | W18: 0.7055 | X18: 0.5355 | Y18: 0.5 | Z18: 0.4815
... B37: 31 | C37: 0.5965 | D37: 0.6045 | E37: 0.594 | F37: 0.5985 | G37: 0.622 | H37: 0.6835 | I37: 0.8205 | J37: 0.9145 | K37: 1.088 | L37: 1.077 | M37: 1.21 | N37: 1.2085 | O37: 1.2325 | P37: 1.122 | Q37: 1.146 | R37: 1.141 | S37: 1.072 | T37: 0.981 | U37: 0.9485 | V37: 0.931 | W37: 0.851 | X37: 0.6945 | Y37: 0.6125 | Z37: 0.547
Y38: ИТОГО | Z38: 63746.16
A39: Счетчик № | B39: 34891189
A40: Тр.тока (коэф) | B40: 120
B41: 1 | C41: 0.7145 | D41: 0.7135 | E41: 0.7585 | F41: 0.725 | G41: 0.717 | H41: 0.7355 | I41: 0.71 | J41: 0.745 | K41: 0.7335 | L41: 0.725 | M41: 0.7675 | N41: 0.758 | O41: 0.7495 | P41: 0.7315 | Q41: 0.744 | R41: 0.7455 | S41: 0.7575 | T41: 0.7755 | U41: 0.7555 | V41: 0.758 | W41: 0.747 | X41: 0.7465 | Y41: 0.7565 | Z41: 0.7315
B42: 2 | C42: 0.713 | D42: 0.718 | E42: 0.72 | F42: 0.763 | G42: 0.7255 | H42: 0.739 | I42: 0.7265 | J42: 0.7195 | K42: 0.767 | L42: 0.7455 | M42: 0.7445 | N42: 0.743 | O42: 0.7035 | P42: 0.7345 | Q42: 0.741 | R42: 0.7425 | S42: 0.7655 | T42: 0.7685 | U42: 0.7835 | V42: 0.7795 | W42: 0.743 | X42: 0.7495 | Y42: 0.761 | Z42: 0.767
B43: 3 | C43: 0.7465 | D43: 0.751 | E43: 0.7435 | F43: 0.7325 | G43: 0.7475 | H43: 0.7075 | I43: 0.773 | J43: 0.8145 | K43: 0.8355 | L43: 0.8545 | M43: 0.8495 | N43: 0.8855 | O43: 0.852 | P43: 0.891 | Q43: 0.843 | R43: 0.793 | S43: 0.8015 | T43: 0.7255 | U43: 0.7615 | V43: 0.802 | W43: 0.755 | X43: 0.758 | Y43: 0.779 | Z43: 0.7905
B44: 4 | C44: 0.7675 | D44: 0.762 | E44: 0.7605 | F44: 0.781 | G44: 0.7875 | H44: 0.748 | I44: 0.807 | J44: 0.8395 | K44: 0.827 | L44: 0.861 | M44: 0.9365 | N44: 0.8745 | O44: 0.899 | P44: 0.866 | Q44: 0.8855 | R44: 0.805 | S44: 0.776 | T44: 0.7475 | U44: 0.79 | V44: 0.772 | W44: 0.775 | X44: 0.7545 | Y44: 0.76 | Z44: 0.7665
B45: 5 | C45: 0.786 | D45: 0.7795 | E45: 0.755 | F45: 0.782 | G45: 0.804 | H45: 0.791 | I45: 0.9565 | J45: 0.9835 | K45: 0.995 | L45: 1.011 | M45: 1.1005 | N45: 0.9885 | O45: 0.898 | P45: 0.8155 | Q45: 0.799 | R45: 0.8175 | S45: 0.8255 | T45: 0.785 | U45: 0.8155 | V45: 0.793 | W45: 0.839 | X45: 0.803 | Y45: 0.8185 | Z45: 0.793
B46: 6 | C46: 0.806 | D46: 0.8125 | E46: 0.8305 | F46: 0.828 | G46: 0.8585 | H46: 0.821 | I46: 0.868 | J46: 0.916 | K46: 0.9225 | L46: 0.9745 | M46: 0.9975 | N46: 1.0275 | O46: 1.0295 | P46: 0.943 | Q46: 0.914 | R46: 0.8325 | S46: 0.824 | T46: 0.7755 | U46: 0.7845 | V46: 0.767 | W46: 0.7805 | X46: 0.8015 | Y46: 0.804 | Z46: 0.7665
B47: 7 | C47: 0.775 | D47: 0.765 | E47: 0.79 | F47: 0.775 | G47: 0.79 | H47: 0.7825 | I47: 0.81 | J47: 0.808 | K47: 0.7905 | L47: 0.8055 | M47: 0.8095 | N47: 0.816 | O47: 0.857 | P47: 0.8175 | Q47: 0.7975 | R47: 0.793 | S47: 0.8295 | T47: 0.8085 | U47: 0.8115 | V47: 0.7895 | W47: 0.7965 | X47: 0.803 | Y47: 0.808 | Z47: 0.763
B48: 8 | C48: 0.7655 | D48: 0.798 | E48: 0.796 | F48: 0.837 | G48: 0.8195 | H48: 0.7985 | I48: 0.7855 | J48: 0.764 | K48: 0.8265 | L48: 0.853 | M48: 0.848 | N48: 0.82 | O48: 0.8615 | P48: 0.941 | Q48: 1.059 | R48: 0.985 | S48: 0.9765 | T48: 0.958 | U48: 0.9495 | V48: 0.941 | W48: 0.9395 | X48: 0.9595 | Y48: 0.9365 | Z48: 0.9095
B49: 9 | C49: 0.885 | D49: 0.866 | E49: 0.8835 | F49: 0.878 | G49: 0.921 | H49: 0.896 | I49: 1.112 | J49: 1.2015 | K49: 1.4565 | L49: 1.4905 | M49: 1.7465 | N49: 1.7665 | O49: 1.9285 | P49: 1.8975 | Q49: 1.6895 | R49: 1.73 | S49: 1.683 | T49: 1.5725 | U49: 1.567 | V49: 1.46 | W49: 1.181 | X49: 1.0515 | Y49: 1.012 | Z49: 0.9925
B50: 10 | C50: 0.9895 | D50: 0.9725 | E50: 0.9505 | F50: 0.937 | G50: 0.9865 | H50: 1.0455 | I50: 1.424 | J50: 1.551 | K50: 1.679 | L50: 1.8355 | M50: 1.782 | N50: 1.771 | O50: 1.8045 | P50: 1.4385 | Q50: 1.3415 | R50: 1.55 | S50: 1.432 | T50: 1.53 | U50: 1.6435 | V50: 1.6725 | W50: 1.648 | X50: 1.282 | Y50: 1.2335 | Z50: 1.447
B51: 11 | C51: 1.5735 | D51: 1.583 | E51: 1.535 | F51: 1.5475 | G51: 1.4665 | H51: 1.417 | I51: 1.6855 | J51: 1.7105 | K51: 1.7225 | L51: 1.717 | M51: 1.571 | N51: 1.4735 | O51: 1.768 | P51: 1.6555 | Q51: 1.6165 | R51: 1.5805 | S51: 1.502 | T51: 1.5725 | U51: 1.6705 | V51: 1.604 | W51: 1.257 | X51: 1.069 | Y51: 1.019 | Z51: 0.9475
B52: 12 | C52: 0.932 | D52: 0.9385 | E52: 0.9275 | F52: 0.9405 | G52: 0.9375 | H52: 1.0665 | I52: 1.2895 | J52: 1.291 | K52: 1.4275 | L52: 1.5145 | M52: 1.608 | N52: 1.66 | O52: 1.7235 | P52: 1.9295 | Q52: 1.8335 | R52: 1.826 | S52: 1.7695 | T52: 1.787 | U52: 1.7245 | V52: 1.679 | W52: 1.2985 | X52: 1.034 | Y52: 0.9945 | Z52: 0.9835
... B71: 31 | C71: 0.667 | D71: 0.6355 | E71: 0.605 | F71: 0.6235 | G71: 0.6125 | H71: 0.667 | I71: 0.8225 | J71: 0.8855 | K71: 1.121 | L71: 1.3175 | M71: 1.499 | N71: 1.4785 | O71: 1.2815 | P71: 1.015 | Q71: 1.14 | R71: 1.406 | S71: 1.304 | T71: 1.157 | U71: 1.187 | V71: 1.1165 | W71: 0.856 | X71: 0.6885 | Y71: 0.6745 | Z71: 0.6615
Y72: ИТОГО | Z72: 98725.32
A73: Счетчик № | B73: 39790894
A74: Тр.тока (коэф) | B74: 20
B75: 1 | C75: 1.04 | D75: 1.0535 | E75: 1.027 | F75: 1.06 | G75: 1.0405 | H75: 1.0155 | I75: 1.052 | J75: 1.0775 | K75: 1.0355 | L75: 1.076 | M75: 1.058 | N75: 1.0665 | O75: 1.074 | P75: 1.016 | Q75: 1.042 | R75: 1.084 | S75: 1.0745 | T75: 1.0535 | U75: 1.11 | V75: 1.0785 | W75: 1.105 | X75: 1.082 | Y75: 1.1145 | Z75: 1.0905
B76: 2 | C76: 1.0745 | D76: 1.095 | E76: 1.0685 | F76: 1.062 | G76: 1.045 | H76: 1.1135 | I76: 1.0585 | J76: 1.07 | K76: 1.04 | L76: 1.038 | M76: 1.0085 | N76: 0.961 | O76: 1.0215 | P76: 1.0025 | Q76: 0.9635 | R76: 1.0355 | S76: 1.0515 | T76: 1.036 | U76: 1.109 | V76: 1.1075 | W76: 1.0885 | X76: 1.105 | Y76: 1.112 | Z76: 1.054
...

Sheet Summa
A1: Сведения
G2: о фактическом почасовом расходе электрической энергии за Январь 2020 года ОАО "Аньковское"
B3: Договор №29 | X3: Уровень СН2
B5: Число расчетного месяца | C5: Время суток
C6: 0.00-1.00 | D6: 1.00-2.00 | E6: 2.00-3.00 | F6: 3.00-4.00 | G6: 4.00-5.00 | H6: 5.00-6.00 | I6: 6.00-7.00 | J6: 7.00-8.00 | K6: 8.00-9.00 | L6: 9.00-10.00 | M6: 10.00-11.00 | N6: 11.00-12.00 | O6: 12.00-13.00 | P6: 13.00-14.00 | Q6: 14.00-15.00 | R6: 15.00-16.00 | S6: 16.00-17.00 | T6: 17.00-18.00 | U6: 18.00-19.00 | V6: 19.00-20.00 | W6: 20.00-21.00 | X6: 21.00-22.00 | Y6: 22.00-23.00 | Z6: 23.00-24.00
B7: 1 | C7: =Worksheet!C7*120 + Worksheet!C41*120 + Worksheet!C75*20 -> 0 | D7: =Worksheet!D7*120 + Worksheet!D41*120 + Worksheet!D75*20 -> 0 | E7: =Worksheet!E7*120 + Worksheet!E41*120 + Worksheet!E75*20 -> 0 | F7: =Worksheet!F7*120 + Worksheet!F41*120 + Worksheet!F75*20 -> 0 | G7: =Worksheet!G7*120 + Worksheet!G41*120 + Worksheet!G75*20 -> 0 | H7: =Worksheet!H7*120 + Worksheet!H41*120 + Worksheet!H75*20 -> 0 | I7: =Worksheet!I7*120 + Worksheet!I41*120 + Worksheet!I75*20 -> 0 | J7: =Worksheet!J7*120 + Worksheet!J41*120 + Worksheet!J75*20 -> 0 | ... Z7: =Worksheet!Z7*120 + Worksheet!Z41*120 + Worksheet!Z75*20 -> 0
B8: 2 | C8: =Worksheet!C8*120 + Worksheet!C42*120 + Worksheet!C76*20 -> 0 | D8: =Worksheet!D8*120 + Worksheet!D42*120 + Worksheet!D76*20 -> 0 | E8: =Worksheet!E8*120 + Worksheet!E42*120 + Worksheet!E76*20 -> 0 | F8: =Worksheet!F8*120 + Worksheet!F42*120 + Worksheet!F76*20 -> 0 | G8: =Worksheet!G8*120 + Worksheet!G42*120 + Worksheet!G76*20 -> 0 | H8: =Worksheet!H8*120 + Worksheet!H42*120 + Worksheet!H76*20 -> 0 | I8: =Worksheet!I8*120 + Worksheet!I42*120 + Worksheet!I76*20 -> 0 | J8: =Worksheet!J8*120 + Worksheet!J42*120 + Worksheet!J76*20 -> 0 | ... Z8: =Worksheet!Z8*120 + Worksheet!Z42*120 + Worksheet!Z76*20 -> 0
B9: 3 | C9: =Worksheet!C9*120 + Worksheet!C43*120 + Worksheet!C77*20 -> 0 | D9: =Worksheet!D9*120 + Worksheet!D43*120 + Worksheet!D77*20 -> 0 | E9: =Worksheet!E9*120 + Worksheet!E43*120 + Worksheet!E77*20 -> 0 | F9: =Worksheet!F9*120 + Worksheet!F43*120 + Worksheet!F77*20 -> 0 | G9: =Worksheet!G9*120 + Worksheet!G43*120 + Worksheet!G77*20 -> 0 | H9: =Worksheet!H9*120 + Worksheet!H43*120 + Worksheet!H77*20 -> 0 | I9: =Worksheet!I9*120 + Worksheet!I43*120 + Worksheet!I77*20 -> 0 | J9: =Worksheet!J9*120 + Worksheet!J43*120 + Worksheet!J77*20 -> 0 | ... Z9: =Worksheet!Z9*120 + Worksheet!Z43*120 + Worksheet!Z77*20 -> 0
B10: 4 | C10: =Worksheet!C10*120 + Worksheet!C44*120 + Worksheet!C78*20 -> 0 | D10: =Worksheet!D10*120 + Worksheet!D44*120 + Worksheet!D78*20 -> 0 | E10: =Worksheet!E10*120 + Worksheet!E44*120 + Worksheet!E78*20 -> 0 | F10: =Worksheet!F10*120 + Worksheet!F44*120 + Worksheet!F78*20 -> 0 | G10: =Worksheet!G10*120 + Worksheet!G44*120 + Worksheet!G78*20 -> 0 | H10: =Worksheet!H10*120 + Worksheet!H44*120 + Worksheet!H78*20 -> 0 | I10: =Worksheet!I10*120 + Worksheet!I44*120 + Worksheet!I78*20 -> 0 | J10: =Worksheet!J10*120 + Worksheet!J44*120 + Worksheet!J78*20 -> 0 | ... Z10: =Worksheet!Z10*120 + Worksheet!Z44*120 + Worksheet!Z78*20 -> 0
B11: 5 | C11: =Worksheet!C11*120 + Worksheet!C45*120 + Worksheet!C79*20 -> 0 | D11: =Worksheet!D11*120 + Worksheet!D45*120 + Worksheet!D79*20 -> 0 | E11: =Worksheet!E11*120 + Worksheet!E45*120 + Worksheet!E79*20 -> 0 | F11: =Worksheet!F11*120 + Worksheet!F45*120 + Worksheet!F79*20 -> 0 | G11: =Worksheet!G11*120 + Worksheet!G45*120 + Worksheet!G79*20 -> 0 | H11: =Worksheet!H11*120 + Worksheet!H45*120 + Worksheet!H79*20 -> 0 | I11: =Worksheet!I11*120 + Worksheet!I45*120 + Worksheet!I79*20 -> 0 | J11: =Worksheet!J11*120 + Worksheet!J45*120 + Worksheet!J79*20 -> 0 | ... Z11: =Worksheet!Z11*120 + Worksheet!Z45*120 + Worksheet!Z79*20 -> 0
B12: 6 | C12: =Worksheet!C12*120 + Worksheet!C46*120 + Worksheet!C80*20 -> 0 | D12: =Worksheet!D12*120 + Worksheet!D46*120 + Worksheet!D80*20 -> 0 | E12: =Worksheet!E12*120 + Worksheet!E46*120 + Worksheet!E80*20 -> 0 | F12: =Worksheet!F12*120 + Worksheet!F46*120 + Worksheet!F80*20 -> 0 | G12: =Worksheet!G12*120 + Worksheet!G46*120 + Worksheet!G80*20 -> 0 | H12: =Worksheet!H12*120 + Worksheet!H46*120 + Worksheet!H80*20 -> 0 | I12: =Worksheet!I12*120 + Worksheet!I46*120 + Worksheet!I80*20 -> 0 | J12: =Worksheet!J12*120 + Worksheet!J46*120 + Worksheet!J80*20 -> 0 | ... Z12: =Worksheet!Z12*120 + Worksheet!Z46*120 + Worksheet!Z80*20 -> 0
B13: 7 | C13: =Worksheet!C13*120 + Worksheet!C47*120 + Worksheet!C81*20 -> 0 | D13: =Worksheet!D13*120 + Worksheet!D47*120 + Worksheet!D81*20 -> 0 | E13: =Worksheet!E13*120 + Worksheet!E47*120 + Worksheet!E81*20 -> 0 | F13: =Worksheet!F13*120 + Worksheet!F47*120 + Worksheet!F81*20 -> 0 | G13: =Worksheet!G13*120 + Worksheet!G47*120 + Worksheet!G81*20 -> 0 | H13: =Worksheet!H13*120 + Worksheet!H47*120 + Worksheet!H81*20 -> 0 | I13: =Worksheet!I13*120 + Worksheet!I47*120 + Worksheet!I81*20 -> 0 | J13: =Worksheet!J13*120 + Worksheet!J47*120 + Worksheet!J81*20 -> 0 | ... Z13: =Worksheet!Z13*120 + Worksheet!Z47*120 + Worksheet!Z81*20 -> 0
B14: 8 | C14: =Worksheet!C14*120 + Worksheet!C48*120 + Worksheet!C82*20 -> 0 | D14: =Worksheet!D14*120 + Worksheet!D48*120 + Worksheet!D82*20 -> 0 | E14: =Worksheet!E14*120 + Worksheet!E48*120 + Worksheet!E82*20 -> 0 | F14: =Worksheet!F14*120 + Worksheet!F48*120 + Worksheet!F82*20 -> 0 | G14: =Worksheet!G14*120 + Worksheet!G48*120 + Worksheet!G82*20 -> 0 | H14: =Worksheet!H14*120 + Worksheet!H48*120 + Worksheet!H82*20 -> 0 | I14: =Worksheet!I14*120 + Worksheet!I48*120 + Worksheet!I82*20 -> 0 | J14: =Worksheet!J14*120 + Worksheet!J48*120 + Worksheet!J82*20 -> 0 | ... Z14: =Worksheet!Z14*120 + Worksheet!Z48*120 + Worksheet!Z82*20 -> 0
B15: 9 | C15: =Worksheet!C15*120 + Worksheet!C49*120 + Worksheet!C83*20 -> 0 | D15: =Worksheet!D15*120 + Worksheet!D49*120 + Worksheet!D83*20 -> 0 | E15: =Worksheet!E15*120 + Worksheet!E49*120 + Worksheet!E83*20 -> 0 | F15: =Worksheet!F15*120 + Worksheet!F49*120 + Worksheet!F83*20 -> 0 | G15: =Worksheet!G15*120 + Worksheet!G49*120 + Worksheet!G83*20 -> 0 | H15: =Worksheet!H15*120 + Worksheet!H49*120 + Worksheet!H83*20 -> 0 | I15: =Worksheet!I15*120 + Worksheet!I49*120 + Worksheet!I83*20 -> 0 | J15: =Worksheet!J15*120 + Worksheet!J49*120 + Worksheet!J83*20 -> 0 | ... Z15: =Worksheet!Z15*120 + Worksheet!Z49*120 + Worksheet!Z83*20 -> 0
B16: 10 | C16: =Worksheet!C16*120 + Worksheet!C50*120 + Worksheet!C84*20 -> 0 | D16: =Worksheet!D16*120 + Worksheet!D50*120 + Worksheet!D84*20 -> 0 | E16: =Worksheet!E16*120 + Worksheet!E50*120 + Worksheet!E84*20 -> 0 | F16: =Worksheet!F16*120 + Worksheet!F50*120 + Worksheet!F84*20 -> 0 | G16: =Worksheet!G16*120 + Worksheet!G50*120 + Worksheet!G84*20 -> 0 | H16: =Worksheet!H16*120 + Worksheet!H50*120 + Worksheet!H84*20 -> 0 | I16: =Worksheet!I16*120 + Worksheet!I50*120 + Worksheet!I84*20 -> 0 | J16: =Worksheet!J16*120 + Worksheet!J50*120 + Worksheet!J84*20 -> 0 | ... Z16: =Worksheet!Z16*120 + Worksheet!Z50*120 + Worksheet!Z84*20 -> 0
B17: 11 | C17: =Worksheet!C17*120 + Worksheet!C51*120 + Worksheet!C85*20 -> 0 | D17: =Worksheet!D17*120 + Worksheet!D51*120 + Worksheet!D85*20 -> 0 | E17: =Worksheet!E17*120 + Worksheet!E51*120 + Worksheet!E85*20 -> 0 | F17: =Worksheet!F17*120 + Worksheet!F51*120 + Worksheet!F85*20 -> 0 | G17: =Worksheet!G17*120 + Worksheet!G51*120 + Worksheet!G85*20 -> 0 | H17: =Worksheet!H17*120 + Worksheet!H51*120 + Worksheet!H85*20 -> 0 | I17: =Worksheet!I17*120 + Worksheet!I51*120 + Worksheet!I85*20 -> 0 | J17: =Worksheet!J17*120 + Worksheet!J51*120 + Worksheet!J85*20 -> 0 | ... Z17: =Worksheet!Z17*120 + Worksheet!Z51*120 + Worksheet!Z85*20 -> 0
B18: 12 | C18: =Worksheet!C18*120 + Worksheet!C52*120 + Worksheet!C86*20 -> 0 | D18: =Worksheet!D18*120 + Worksheet!D52*120 + Worksheet!D86*20 -> 0 | E18: =Worksheet!E18*120 + Worksheet!E52*120 + Worksheet!E86*20 -> 0 | F18: =Worksheet!F18*120 + Worksheet!F52*120 + Worksheet!F86*20 -> 0 | G18: =Worksheet!G18*120 + Worksheet!G52*120 + Worksheet!G86*20 -> 0 | H18: =Worksheet!H18*120 + Worksheet!H52*120 + Worksheet!H86*20 -> 0 | I18: =Worksheet!I18*120 + Worksheet!I52*120 + Worksheet!I86*20 -> 0 | J18: =Worksheet!J18*120 + Worksheet!J52*120 + Worksheet!J86*20 -> 0 | ... Z18: =Worksheet!Z18*120 + Worksheet!Z52*120 + Worksheet!Z86*20 -> 0
... B37: 31 | C37: =Worksheet!C37*120 + Worksheet!C71*120 + Worksheet!C105*20 -> 0 | D37: =Worksheet!D37*120 + Worksheet!D71*120 + Worksheet!D105*20 -> 0 | E37: =Worksheet!E37*120 + Worksheet!E71*120 + Worksheet!E105*20 -> 0 | F37: =Worksheet!F37*120 + Worksheet!F71*120 + Worksheet!F105*20 -> 0 | G37: =Worksheet!G37*120 + Worksheet!G71*120 + Worksheet!G105*20 -> 0 | H37: =Worksheet!H37*120 + Worksheet!H71*120 + Worksheet!H105*20 -> 0 | I37: =Worksheet!I37*120 + Worksheet!I71*120 + Worksheet!I105*20 -> 0 | J37: =Worksheet!J37*120 + Worksheet!J71*120 + Worksheet!J105*20 -> 0 | ... Z37: =Worksheet!Z37*120 + Worksheet!Z71*120 + Worksheet!Z105*20 -> 0
Y38: Сумма | Z38: =SUM(C7:Z37) -> 0
B41: Главный энергетик_________________Кабанов С.В. | Q41: М.П.

Sheet Rashod
A1: СВЕДЕНИЯ
A2: о расходе электроэнергии по ОАО "Аньковское", за Январь 2020 года.
A3: № п/п | B3: Наименование точки учета | C3: Номер прибора учета | D3: Показания прибора учета | F3: Расчетный к-т | G3: Расход э/энергии (кВтч)
D4: Конечное | E4: Начальное
A5: 1 | B5: 2 | C5: 3 | D5: 4 | E5: 5 | F5: 6 | G5: 7
A6: 1. | B6: Потребление электроэнергии Потребителем
A7: 1.1 | B7: "Аньково" ВЛ-102 ЗТП-400 Т-1 активный | C7: 25506893 | D7: 25146.055 | E7: 24614.837 | F7: 120 | G7: 63746.16
A8: 1.2 | B8: "Аньково" ВЛ-102 ЗТП-400 Т-1 реактивный | C8: 25506893 | D8: 15038.031 | E8: 14833.833 | F8: 120 | G8: 24503.88
A9: 1.3 | B9: "Аньково" ВЛ-102 ЗТП-400 Т-2 активный | C9: 34891189 | D9: 16757.698 | E9: 15934.987 | F9: 120 | G9: 98725.32
A10: 1.4 | B10: "Аньково" ВЛ-102 ЗТП-400 Т-2 реактивный | C10: 34891189 | D10: 8722.665 | E10: 8276.067 | F10: 120 | G10: 53591.76
A11: 1.5 | B11: "Аньково" ВЛ-102 КТП-400 Очистные сооружения | C11: 39790894 | D11: 1403.452 | E11: 583.27 | F11: 20 | G11: 16403.64
A12: 2. | B12: Потери э/э оплачиваемые активные | G12: 3777
A13: 2.1
A14: 3. | B14: Потери э/э оплачиваемые реактивные | G14: 20464
A15: 3.1 | B15: Реактивное потребление по "Правилу"
A16: 3.2
A17: 4. | B17: Замена прибора учета э/э
A18: 4.1
A19: 4.2 | B19: ИТОГО ОБЩИЙ РАСХОД (С ПОТЕРЯМИ), АКТИВНЫЙ | G19: 182652.12
B20: ИТОГО ОБЩИЙ РАСХОД (С ПОТЕРЯМИ), РЕАКТИВНЫЙ | G20: 98559.64
F23: М. П.
B25: Исполнитель_________________Кабанов С.В.
B27: телефон (49353) 33102

Sheet Svedeniya
A1: СВЕДЕНИЯ
A2: о расходе электроэнергии за Я Н В А Р Ь 2020 г.
A4: ОАО "Аньковское" № ЭСК-29 от 01.07.2014 г.
A7: Наименование объекта | B7: № фидера | C7: № КТП | D7: Тип счетчика | E7: № счетчика | F7: Дата снятия показаний счетчика | G7: Показания счетчика | I7: Разность показаний | K7: Коэффи- циент счетчика | L7: Расход электроэнергии (кВтч)
G8: начальное | H8: конечное
A9: 1 | B9: 2 | C9: 3 | D9: 4 | E9: 5 | F9: 6 | G9: 7 | H9: 8 | I9: 9 | K9: 10 | L9: 11
A10: Потребление электроэнергии Потребителем
A12: Потребители с макс. мощностью от 150кВт до 670кВт, СН-2
A13: 1.1. ПС "Аньково", ВЛ-10кВ №102, 107 | B13: РУ-0,4кВ ЗТП 2*400кВА | C13: Т-1 | D13: Меркурий 230 ART-01 | E13: 25506893 | F13: 01.01.2020 | G13: по профилю потребителя | L13: 63746.16
C14: Т-2 | D14: Меркурий 236 ART-03 | E14: 34891189 | F14: 01.01.2020 | G14: по профилю потребителя | L14: 98725.32
A15: ИТОГО: | B15: 162471.48
A16: Потери э/э оплачиваемые: | B16: 3474
A17: ВСЕГО: от 150кВт до 670кВт | B17: 165945.48
A19: Потребители с макс. Мощностью менее 150кВт, СН-2
A22: 1.1. "Очистные сооружения" | B22: РУ-0,4кВ КТП-100кВа | D22: Меркурий 230 ART-01 | E22: 39790894 | F22: 01.01.2020 | G22: по профилю потребителя | L22: 16403.64
A25: Потери э/э оплачиваемые: | B25: 303
A28: ИТОГО: менее 150кВт | B28: 16706.64
A35: ИТОГО по договору №ЭСК-29 | L35: 182652.12
A37: Генеральный директор____________________________________________________
A40: Исполнитель:______________________________ | I40: ______________________________ /дата/
